<?xml version="1.0"?>

<robot name="RobotSystem" xmlns:xacro="http://www.ros.org/wiki/xacro">

  <xacro:arg name="is_sim" default="true"/>

  <xacro:include filename="inertial_macros.xacro" />
  <xacro:include filename="robot.gazebo.xacro" />
  <xacro:include filename="robot.ros2_control.xacro" />

  <material name="white">
   <color rgba="1 1 1 1"/>
  </material>
  <material name="green">
   <color rgba="0 1 0 1"/>
  </material>
  <material name="gray">
   <color rgba="0.5 0.5 0.5 1"/>
  </material>


 <link name="base_footprint" />

<link name="base_link">
   <visual>
     <geometry>
       <cylinder radius="0.17" length="0.102"/>
     </geometry>
     <origin xyz="0 0 0" rpy="0 0 0"/>
     <material name="white"/>
   </visual>
   <collision>
     <geometry>
       <cylinder radius="0.17" length="0.102"/>
     </geometry>
     <origin xyz="0 0 0" rpy="0 0 0"/>
   </collision>
   <xacro:cylinder_inertia m="4" r="0.17" l="0.102" o_xyz="0 0 0" o_rpy="0 0 0" />
</link>

<!-- Base link -->
 <joint name="base_link_joint" type="fixed">
   <parent link="base_footprint"/>
   <child link="base_link"/>
   <origin xyz="0 0 0.0835" rpy="0 0 0"/>
</joint>

<link name="caster_wheel">
   <visual>
      <geometry>
        <sphere radius="0.0325"/>
      </geometry>
      <origin xyz="0 0 0" rpy="0 0 0"/>
      <material name="gray"/>
   </visual>
   <collision>
      <geometry>
        <sphere radius="0.0325"/>
      </geometry>
      <origin xyz="0 0 0" rpy="0 0 0"/>
   </collision>
   <xacro:sphere_inertia m="0.2" r="0.0325" o_xyz="0 0 0" o_rpy="0 0 0" />
</link>

<joint name="caster_wheel_joint" type="fixed">
    <parent link="base_link"/>
    <child link="caster_wheel"/>
    <origin xyz="0.14 0 -0.051" rpy="0 0 0"/>
</joint>

<link name="left_wheel">
  <visual>
      <geometry>
          <cylinder radius="0.0325" length="0.036"/>
      </geometry>
      <material name="gray"/>
      <origin xyz="0 0 0" rpy="0 0 0" />
  </visual>
  <collision>
    <geometry>
        <cylinder radius="0.0325" length="0.036"/>
    </geometry>
    <origin xyz="0 0 0" rpy="0 0 0" />
</collision>
<xacro:cylinder_inertia m="1" r="0.0325" l="0.036" o_xyz="0 0 0" o_rpy="0 0 0" />
</link>

<joint name="left_wheel_joint" type="continuous">
  <parent link="base_link"/>
  <child link="left_wheel"/>
  <origin xyz="0 0.188 -0.051" rpy="1.57 0 0" />
  <axis xyz="0 0 -1"/>
</joint>

<link name="right_wheel">
  <visual>
      <geometry>
          <cylinder radius="0.0325" length="0.036"/>
      </geometry>
      <material name="gray"/>
      <origin xyz="0 0 0" rpy="0 0 0" />
  </visual>
  <collision>
    <geometry>
        <cylinder radius="0.0325" length="0.036"/>
    </geometry>
    <origin xyz="0 0 0" rpy="0 0 0" />
</collision>
<xacro:cylinder_inertia m="1" r="0.0325" l="0.036" o_xyz="0 0 0" o_rpy="0 0 0" />
</link>

<joint name="right_wheel_joint" type="continuous">
  <parent link="base_link"/>
  <child link="right_wheel"/>
  <origin xyz="0 -0.188 -0.051" rpy="1.57 0 0" />
  <axis xyz="0 0 -1"/>
</joint>

<link name="caster_wheel_back">
   <visual>
      <geometry>
        <sphere radius="0.0325"/>
      </geometry>
      <origin xyz="0 0 0" rpy="0 0 0"/>
      <material name="gray"/>
   </visual>
   <collision>
      <geometry>
        <sphere radius="0.0325"/>
      </geometry>
      <origin xyz="0 0 0" rpy="0 0 0"/>
   </collision>
   <xacro:sphere_inertia m="0.2" r="0.0325" o_xyz="0 0 0" o_rpy="0 0 0" />
</link>

<joint name="caster_wheel_back_joint" type="fixed">
    <parent link="base_link"/>
    <child link="caster_wheel_back"/>
    <origin xyz="-0.14 0 -0.051" rpy="0 0 0"/>
</joint>

</robot>